Workbook

Sheet README
A1: EV-ICIO parameter workbook | Adata_v6
A3: Release | B3: v6.0 | 2022 ICIO 50-sector baseline and country-specific 15-item BOM profiles
A4: Only editable BOM input | B4: BOM_raw.bom_share. EVmodel_v5 and MC_v3 read BOM_raw directly; they do not depend on cached Excel formula results.
A5: Example profiles | B5: CHN, DEU, JPN, KOR, MEX, USA and mandatory OTHERS. All seven initially copy the same supplied figure.
A6: Matching rule | B6: For EV producer c, use the exact uppercase country_code profile when present; otherwise use OTHERS.
A7: Per-profile validity | B7: Each profile must contain exactly 15 unique item_id values, the required seven groups, non-negative shares, and bom_share summing to 1.
A8: beta rule | B8: For economy c and group g: beta_g,c = u_C29,c * b_g,c, where b_g,c is summed from the matched BOM_raw profile.
A9: E-sector split | B9: Within E, C26 uses item_id BMS + VCU; C27 uses MCU + OBC + DCDC + PDU. Weights are recalculated from the matched profile.
A10: Audit sheets | B10: BOM_scenarios, Sector_mapping and Beta_derived are formula-driven displays/QA. They are not R model inputs in v5/MC_v3.
A11: Editing procedure | B11: Change only bom_share in BOM_raw, keep identifiers/groups unchanged, ensure each profile total is 100%, save, then run EVmodel_v5 or MC_v3.
A13: Sheet | B13: Purpose | C13: Status | D13: Primary source | E13: Year | F13: Unit | G13: Used by R v5/MC_v3 | H13: Key caution
A14: BOM_raw | B14: Country x 15-item long-format BOM inputs | C14: Rebuilt | D14: User-supplied BOM figure (15 labelled items; bibliographic metadata pending) | E14: n/a | F14: share | G14: Yes; sole BOM input | H14: Edit bom_share only; OTHERS is mandatory.
A15: BOM_scenarios | B15: Seven-profile formula audit and group totals | C15: Rebuilt | D15: BOM_raw | E15: n/a | F15: share | G15: No; audit only | H15: Values update from BOM_raw formulas.
A16: Sector_mapping | B16: Country-specific E split plus other allocation rules | C16: Rebuilt | D16: BOM_raw + modelling rules | E16: n/a | F16: weight/rule | G16: No; audit only | H16: E weights are item-derived, never hardcoded.
A17: Beta_derived | B17: Country match/fallback and beta audit | C17: Formula-driven | D17: BOM_raw + ICIO_intensity | E17: 2022 | F17: coefficient | G17: No; audit only | H17: Shows exact versus OTHERS fallback.
A18: BOM_figure | B18: Source figure and OTHERS/default summary | C18: Updated | D18: User-supplied BOM figure (15 labelled items; bibliographic metadata pending) | E18: n/a | F18: BOM share | G18: Documentation | H18: Full bibliographic metadata remain to be supplied.
A19: ICIO_intensity | B19: C29 intermediate and value-added/TLS shares | C19: Updated | D19: 2022_SML.csv | E19: 2022 | F19: share | G19: Yes | H19: u is the 2022 country-specific intermediate-input budget; VA applies the 1.17 calibration factor.
A20: IMshareM/IMshareC | B20: Legacy imported-origin matrices | C20: Pending user update | D20: Legacy Adata source | E20: 2020 pending replacement | F20: share | G20: Yes | H20: Replace IMshareM/IMshareC with 2022 matrices before the final model run.
A21: Alpha_2020 | B21: Country/system domestic sourcing parameters | C21: Updated | D21: 2022_SML.csv | E21: 2022 | F21: share | G21: Yes | H21: Legacy sheet name retained for compatibility; values are calculated from 2022 ICIO.
A22: Countries/Sectors | B22: ICIO labels and producer flags | C22: Countries preserved; Sectors updated | D22: OECD ICIO 2025 edition metadata | E22: 2022/2025 | F22: code | G22: Yes | H22: Country order is unchanged; the sector list contains 50 activities.
A23: QA | B23: Formula-driven workbook integrity checks | C23: Rebuilt | D23: All v4 parameter sheets | E23: n/a | F23: PASS/FAIL | G23: Audit | H23: Any FAIL must be resolved before modelling.
A25: BOM_raw is deliberately a flat, machine-readable table. Formula caches elsewhere in this workbook are never required by the R programs. | B25: BOM_raw is deliberately a flat, machine-readable table. Formula caches elsewhere in this workbook are never required by the R programs. | C25: BOM_raw is deliberately a flat, machine-readable table. Formula caches elsewhere in this workbook are never required by the R programs. | D25: BOM_raw is deliberately a flat, machine-readable table. Formula caches elsewhere in this workbook are never required by the R programs. | E25: BOM_raw is deliberately a flat, machine-readable table. Formula caches elsewhere in this workbook are never required by the R programs. | F25: BOM_raw is deliberately a flat, machine-readable table. Formula caches elsewhere in this workbook are never required by the R programs. | G25: BOM_raw is deliberately a flat, machine-readable table. Formula caches elsewhere in this workbook are never required by the R programs. | H25: BOM_raw is deliberately a flat, machine-readable table. Formula caches elsewhere in this workbook are never required by the R programs.
... A27: Yellow cells are user inputs; green cells are formulas/derived audit values. | B27: Yellow cells are user inputs; green cells are formulas/derived audit values. | C27: Yellow cells are user inputs; green cells are formulas/derived audit values. | D27: Yellow cells are user inputs; green cells are formulas/derived audit values. | E27: Yellow cells are user inputs; green cells are formulas/derived audit values. | F27: Yellow cells are user inputs; green cells are formulas/derived audit values. | G27: Yellow cells are user inputs; green cells are formulas/derived audit values. | H27: Yellow cells are user inputs; green cells are formulas/derived audit values.

Sheet Countries
A1: Index | B1: ISO3 | C1: Economy | D1: Include_base | E1: EV production 2023 (thousand vehicles) | F1: Criterion | G1: Source
A2: 1 | B2: ARG | C2: Argentina | D2: FALSE | E2: 0 | F2: not positive/not reported | G2: 20250205_car production data.xlsx, Passenger car production
A3: 2 | B3: AUS | C3: Australia | D3: FALSE | F3: not positive/not reported | G3: 20250205_car production data.xlsx, Passenger car production
A4: 3 | B4: AUT | C4: Austria | D4: TRUE | E4: 5.675 | F4: positive 2023 EV passenger-car production | G4: 20250205_car production data.xlsx, Passenger car production
A5: 4 | B5: BEL | C5: Belgium | D5: TRUE | E5: 66.781 | F5: positive 2023 EV passenger-car production | G5: 20250205_car production data.xlsx, Passenger car production
A6: 5 | B6: BGD | C6: Bangladesh | D6: FALSE | F6: not positive/not reported | G6: 20250205_car production data.xlsx, Passenger car production
A7: 6 | B7: BGR | C7: Bulgaria | D7: FALSE | F7: not positive/not reported | G7: 20250205_car production data.xlsx, Passenger car production
A8: 7 | B8: BLR | C8: Belarus | D8: FALSE | F8: not positive/not reported | G8: 20250205_car production data.xlsx, Passenger car production
A9: 8 | B9: BRA | C9: Brazil | D9: FALSE | E9: 0 | F9: not positive/not reported | G9: 20250205_car production data.xlsx, Passenger car production
A10: 9 | B10: BRN | C10: Brunei Darussalam | D10: FALSE | F10: not positive/not reported | G10: 20250205_car production data.xlsx, Passenger car production
A11: 10 | B11: CAN | C11: Canada | D11: FALSE | E11: 0 | F11: not positive/not reported | G11: 20250205_car production data.xlsx, Passenger car production
A12: 11 | B12: CHE | C12: Switzerland | D12: FALSE | F12: not positive/not reported | G12: 20250205_car production data.xlsx, Passenger car production
A13: 12 | B13: CHL | C13: Chile | D13: FALSE | F13: not positive/not reported | G13: 20250205_car production data.xlsx, Passenger car production
A14: 13 | B14: CHN | C14: China (People's Republic of) | D14: TRUE | E14: 8963.171 | F14: positive 2023 EV passenger-car production | G14: 20250205_car production data.xlsx, Passenger car production
A15: 14 | B15: CIV | C15: Côte d'Ivoire | D15: FALSE | F15: not positive/not reported | G15: 20250205_car production data.xlsx, Passenger car production
A16: 15 | B16: CMR | C16: Cameroon | D16: FALSE | F16: not positive/not reported | G16: 20250205_car production data.xlsx, Passenger car production
A17: 16 | B17: COL | C17: Colombia | D17: FALSE | F17: not positive/not reported | G17: 20250205_car production data.xlsx, Passenger car production
A18: 17 | B18: CRI | C18: Costa Rica | D18: FALSE | F18: not positive/not reported | G18: 20250205_car production data.xlsx, Passenger car production
A19: 18 | B19: CYP | C19: Cyprus (1) | D19: FALSE | F19: not positive/not reported | G19: 20250205_car production data.xlsx, Passenger car production
A20: 19 | B20: CZE | C20: Czechia | D20: TRUE | E20: 81.78 | F20: positive 2023 EV passenger-car production | G20: 20250205_car production data.xlsx, Passenger car production
A21: 20 | B21: DEU | C21: Germany | D21: TRUE | E21: 862.436 | F21: positive 2023 EV passenger-car production | G21: 20250205_car production data.xlsx, Passenger car production
A22: 21 | B22: DNK | C22: Denmark | D22: FALSE | F22: not positive/not reported | G22: 20250205_car production data.xlsx, Passenger car production
A23: 22 | B23: EGY | C23: Egypt | D23: FALSE | F23: not positive/not reported | G23: 20250205_car production data.xlsx, Passenger car production
A24: 23 | B24: ESP | C24: Spain | D24: TRUE | E24: 2.985 | F24: positive 2023 EV passenger-car production | G24: 20250205_car production data.xlsx, Passenger car production
A25: 24 | B25: EST | C25: Estonia | D25: FALSE | F25: not positive/not reported | G25: 20250205_car production data.xlsx, Passenger car production
A26: 25 | B26: FIN | C26: Finland | D26: FALSE | E26: 0 | F26: not positive/not reported | G26: 20250205_car production data.xlsx, Passenger car production
A27: 26 | B27: FRA | C27: France | D27: TRUE | E27: 15.736 | F27: positive 2023 EV passenger-car production | G27: 20250205_car production data.xlsx, Passenger car production
A28: 27 | B28: GBR | C28: United Kingdom | D28: TRUE | E28: 24.633 | F28: positive 2023 EV passenger-car production | G28: 20250205_car production data.xlsx, Passenger car production
A29: 28 | B29: GRC | C29: Greece | D29: FALSE | F29: not positive/not reported | G29: 20250205_car production data.xlsx, Passenger car production
A30: 29 | B30: HKG | C30: Hong Kong, China | D30: FALSE | F30: not positive/not reported | G30: 20250205_car production data.xlsx, Passenger car production
A31: 30 | B31: HRV | C31: Croatia | D31: FALSE | F31: not positive/not reported | G31: 20250205_car production data.xlsx, Passenger car production
A32: 31 | B32: HUN | C32: Hungary | D32: FALSE | F32: not positive/not reported | G32: 20250205_car production data.xlsx, Passenger car production
A33: 32 | B33: IDN | C33: Indonesia | D33: FALSE | F33: not positive/not reported | G33: 20250205_car production data.xlsx, Passenger car production
A34: 33 | B34: IND | C34: India | D34: FALSE | F34: not positive/not reported | G34: 20250205_car production data.xlsx, Passenger car production
A35: 34 | B35: IRL | C35: Ireland | D35: FALSE | F35: not positive/not reported | G35: 20250205_car production data.xlsx, Passenger car production
A36: 35 | B36: ISL | C36: Iceland | D36: FALSE | F36: not positive/not reported | G36: 20250205_car production data.xlsx, Passenger car production
A37: 36 | B37: ISR | C37: Israel (2) | D37: FALSE | F37: not positive/not reported | G37: 20250205_car production data.xlsx, Passenger car production
A38: 37 | B38: ITA | C38: Italy | D38: FALSE | E38: 0 | F38: not positive/not reported | G38: 20250205_car production data.xlsx, Passenger car production
A39: 38 | B39: JOR | C39: Jordan | D39: FALSE | F39: not positive/not reported | G39: 20250205_car production data.xlsx, Passenger car production
A40: 39 | B40: JPN | C40: Japan | D40: TRUE | E40: 190.1 | F40: positive 2023 EV passenger-car production | G40: 20250205_car production data.xlsx, Passenger car production
...

Sheet Sectors
A1: Index | B1: ICIO50 code | C1: Industry | D1: ISIC Rev.4
A2: 1 | B2: A01 | C2: Agriculture and hunting | D2: 01
A3: 2 | B3: A02 | C3: Forestry and logging | D3: 02
A4: 3 | B4: A03 | C4: Fishing and aquaculture | D4: 03
A5: 4 | B5: B05 | C5: Mining of coal and lignite | D5: 05
A6: 5 | B6: B06 | C6: Extraction of crude petroleum and natural gas | D6: 06
A7: 6 | B7: B07 | C7: Mining of metal ores | D7: 07
A8: 7 | B8: B08 | C8: Other mining and quarrying | D8: 08
A9: 8 | B9: B09 | C9: Mining support service activities | D9: 09
A10: 9 | B10: C10T12 | C10: Manufacture of food products; beverages and tobacco products | D10: 10, 11, 12
A11: 10 | B11: C13T15 | C11: Manufacture of textiles, wearing apparel, leather and related products | D11: 13, 14, 15
A12: 11 | B12: C16 | C12: Manufacture of wood and of products of wood and cork | D12: 16
A13: 12 | B13: C17_18 | C13: Manufacture of paper and paper products; Printing and reproduction of recorded media | D13: 17, 18
... A51: 50 | B51: T | C51: Activities of households as employers; undifferentiated goods- and services-producing activities of households for own use | D51: 97, 98

Sheet BOM_raw
A1: country_code | B1: country_name | C1: item_id | D1: figure_label | E1: bom_share | F1: group | G1: icio_treatment | H1: origin_rule | I1: source | J1: notes | K1: 396 | L1: 396 | M1: 396
A2: CHN | B2: China | C2: BATTERY_PACK | D2: Battery pack | E2: =35.2%-0.0915 -> 0.2605 | F2: T | G2: C27 explicit input | H2: LEGACY_T | I2: User-supplied BOM figure (15 labelled items; bibliographic metadata pending) | J2: Traction battery pack | K2: 396 | L2: 396 | M2: 396
A3: CHN | B3: China | C3: HIGH_VOLTAGE_HARNESS | D3: High-voltage harness | E3: 0.01 | F3: HV | G3: C29 original-A allocation | H3: ORIGINAL_A | I3: User-supplied BOM figure (15 labelled items; bibliographic metadata pending) | J3: Kept separate from electronic control | K3: 396 | L3: 396 | M3: 396
A4: CHN | B4: China | C4: DRIVE_MOTOR | D4: Drive motor (rear single) | E4: 0.027 | F4: M | G4: C27 explicit input | H4: LEGACY_M | I4: User-supplied BOM figure (15 labelled items; bibliographic metadata pending) | J4: Drive motor | K4: 396 | L4: 396 | M4: 396
A5: CHN | B5: China | C5: MCU | D5: MCU (motor controller) | E5: 0.023 | F5: E | G5: C26/C27 item split | H5: LEGACY_C | I5: User-supplied BOM figure (15 labelled items; bibliographic metadata pending) | J5: E/C27 item | K5: 396 | L5: 396 | M5: 396
A6: CHN | B6: China | C6: REDUCER | D6: Reducer | E6: 0.009 | F6: M | G6: C27 explicit input | H6: LEGACY_M | I6: User-supplied BOM figure (15 labelled items; bibliographic metadata pending) | J6: Included with the drive system | K6: 396 | L6: 396 | M6: 396
A7: CHN | B7: China | C7: OBC | D7: OBC (on-board charger) | E7: 0.006 | F7: E | G7: C26/C27 item split | H7: LEGACY_C | I7: User-supplied BOM figure (15 labelled items; bibliographic metadata pending) | J7: E/C27 item | K7: 396 | L7: 396 | M7: 396
A8: CHN | B8: China | C8: DCDC | D8: DCDC (direct current-direct current converter) | E8: 0.004 | F8: E | G8: C26/C27 item split | H8: LEGACY_C | I8: User-supplied BOM figure (15 labelled items; bibliographic metadata pending) | J8: E/C27 item | K8: 396 | L8: 396 | M8: 396
A9: CHN | B9: China | C9: PDU | D9: PDU (high-voltage distribution box) | E9: 0.007 | F9: E | G9: C26/C27 item split | H9: LEGACY_C | I9: User-supplied BOM figure (15 labelled items; bibliographic metadata pending) | J9: E/C27 item | K9: 396 | L9: 396 | M9: 396
A10: CHN | B10: China | C10: BMS | D10: BMS | E10: 0.011 | F10: E | G10: C26/C27 item split | H10: LEGACY_C | I10: User-supplied BOM figure (15 labelled items; bibliographic metadata pending) | J10: E/C26 item | K10: 396 | L10: 396 | M10: 396
A11: CHN | B11: China | C11: VCU | D11: VCU (vehicle controller) | E11: 0.002 | F11: E | G11: C26/C27 item split | H11: LEGACY_C | I11: User-supplied BOM figure (15 labelled items; bibliographic metadata pending) | J11: E/C26 item | K11: 396 | L11: 396 | M11: 396
A12: CHN | B12: China | C12: BODY | D12: Body | E12: 0.152 | F12: SHARED | G12: Original C29 input structure | H12: ORIGINAL_A | I12: User-supplied BOM figure (15 labelled items; bibliographic metadata pending) | J12: Shared/non-powertrain component | K12: 396 | L12: 396 | M12: 396
A13: CHN | B13: China | C13: INTERIOR_EXTERIOR | D13: Interior and exterior decoration | E13: =9.8%+0.0915 -> 0.1895 | F13: SHARED | G13: Original C29 input structure | H13: ORIGINAL_A | I13: User-supplied BOM figure (15 labelled items; bibliographic metadata pending) | J13: Shared/non-powertrain component | K13: 396 | L13: 396 | M13: 396
A14: CHN | B14: China | C14: CHASSIS | D14: Chassis | E14: 0.137 | F14: SHARED | G14: Original C29 input structure | H14: ORIGINAL_A | I14: User-supplied BOM figure (15 labelled items; bibliographic metadata pending) | J14: Shared/non-powertrain component | K14: 396 | L14: 396 | M14: 396
A15: CHN | B15: China | C15: ELECTRONIC_ELECTRICAL | D15: Electronic and electrical | E15: 0.103 | F15: EE | G15: C26|C27|C29 original-A allocation | H15: ORIGINAL_A | I15: User-supplied BOM figure (15 labelled items; bibliographic metadata pending) | J15: Not included in the narrow three-electric-system total | K15: 396 | L15: 396 | M15: 396
A16: CHN | B16: China | C16: INTELLIGENT_DRIVING | D16: Intelligent driving | E16: 0.059 | F16: I | G16: C26 original-A allocation | H16: ORIGINAL_A | I16: User-supplied BOM figure (15 labelled items; bibliographic metadata pending) | J16: Not included in the narrow three-electric-system total | K16: 396 | L16: 396 | M16: 396
A17: DEU | B17: Germany | C17: BATTERY_PACK | D17: Battery pack | E17: =35.2%-0.0544 -> 0.2976 | F17: T | G17: C27 explicit input | H17: LEGACY_T | I17: User-supplied BOM figure (15 labelled items; bibliographic metadata pending) | J17: Traction battery pack | K17: 396 | L17: 396 | M17: 396
A18: DEU | B18: Germany | C18: HIGH_VOLTAGE_HARNESS | D18: High-voltage harness | E18: 0.01 | F18: HV | G18: C29 original-A allocation | H18: ORIGINAL_A | I18: User-supplied BOM figure (15 labelled items; bibliographic metadata pending) | J18: Kept separate from electronic control | K18: 396 | L18: 396 | M18: 396
A19: DEU | B19: Germany | C19: DRIVE_MOTOR | D19: Drive motor (rear single) | E19: 0.027 | F19: M | G19: C27 explicit input | H19: LEGACY_M | I19: User-supplied BOM figure (15 labelled items; bibliographic metadata pending) | J19: Drive motor | K19: 396 | L19: 396 | M19: 396
A20: DEU | B20: Germany | C20: MCU | D20: MCU (motor controller) | E20: 0.023 | F20: E | G20: C26/C27 item split | H20: LEGACY_C | I20: User-supplied BOM figure (15 labelled items; bibliographic metadata pending) | J20: E/C27 item | K20: 396 | L20: 396 | M20: 396
A21: DEU | B21: Germany | C21: REDUCER | D21: Reducer | E21: 0.009 | F21: M | G21: C27 explicit input | H21: LEGACY_M | I21: User-supplied BOM figure (15 labelled items; bibliographic metadata pending) | J21: Included with the drive system | K21: 396 | L21: 396 | M21: 396
A22: DEU | B22: Germany | C22: OBC | D22: OBC (on-board charger) | E22: 0.006 | F22: E | G22: C26/C27 item split | H22: LEGACY_C | I22: User-supplied BOM figure (15 labelled items; bibliographic metadata pending) | J22: E/C27 item | K22: 396 | L22: 396 | M22: 396
A23: DEU | B23: Germany | C23: DCDC | D23: DCDC (direct current-direct current converter) | E23: 0.004 | F23: E | G23: C26/C27 item split | H23: LEGACY_C | I23: User-supplied BOM figure (15 labelled items; bibliographic metadata pending) | J23: E/C27 item | K23: 396 | L23: 396 | M23: 396
A24: DEU | B24: Germany | C24: PDU | D24: PDU (high-voltage distribution box) | E24: 0.007 | F24: E | G24: C26/C27 item split | H24: LEGACY_C | I24: User-supplied BOM figure (15 labelled items; bibliographic metadata pending) | J24: E/C27 item | K24: 396 | L24: 396 | M24: 396
A25: DEU | B25: Germany | C25: BMS | D25: BMS | E25: 0.011 | F25: E | G25: C26/C27 item split | H25: LEGACY_C | I25: User-supplied BOM figure (15 labelled items; bibliographic metadata pending) | J25: E/C26 item | K25: 396 | L25: 396 | M25: 396
A26: DEU | B26: Germany | C26: VCU | D26: VCU (vehicle controller) | E26: 0.002 | F26: E | G26: C26/C27 item split | H26: LEGACY_C | I26: User-supplied BOM figure (15 labelled items; bibliographic metadata pending) | J26: E/C26 item | K26: 396 | L26: 396 | M26: 396
A27: DEU | B27: Germany | C27: BODY | D27: Body | E27: 0.152 | F27: SHARED | G27: Original C29 input structure | H27: ORIGINAL_A | I27: User-supplied BOM figure (15 labelled items; bibliographic metadata pending) | J27: Shared/non-powertrain component | K27: 396 | L27: 396 | M27: 396
A28: DEU | B28: Germany | C28: INTERIOR_EXTERIOR | D28: Interior and exterior decoration | E28: =9.8%+0.0544 -> 0.1524 | F28: SHARED | G28: Original C29 input structure | H28: ORIGINAL_A | I28: User-supplied BOM figure (15 labelled items; bibliographic metadata pending) | J28: Shared/non-powertrain component | K28: 396 | L28: 396 | M28: 396
A29: DEU | B29: Germany | C29: CHASSIS | D29: Chassis | E29: 0.137 | F29: SHARED | G29: Original C29 input structure | H29: ORIGINAL_A | I29: User-supplied BOM figure (15 labelled items; bibliographic metadata pending) | J29: Shared/non-powertrain component | K29: 396 | L29: 396 | M29: 396
A30: DEU | B30: Germany | C30: ELECTRONIC_ELECTRICAL | D30: Electronic and electrical | E30: 0.103 | F30: EE | G30: C26|C27|C29 original-A allocation | H30: ORIGINAL_A | I30: User-supplied BOM figure (15 labelled items; bibliographic metadata pending) | J30: Not included in the narrow three-electric-system total | K30: 396 | L30: 396 | M30: 396
A31: DEU | B31: Germany | C31: INTELLIGENT_DRIVING | D31: Intelligent driving | E31: 0.059 | F31: I | G31: C26 original-A allocation | H31: ORIGINAL_A | I31: User-supplied BOM figure (15 labelled items; bibliographic metadata pending) | J31: Not included in the narrow three-electric-system total | K31: 396 | L31: 396 | M31: 396
A32: JPN | B32: Japan | C32: BATTERY_PACK | D32: Battery pack | E32: =35.2%-0.11865 -> 0.23335 | F32: T | G32: C27 explicit input | H32: LEGACY_T | I32: User-supplied BOM figure (15 labelled items; bibliographic metadata pending) | J32: Traction battery pack | K32: 396 | L32: 396 | M32: 396
A33: JPN | B33: Japan | C33: HIGH_VOLTAGE_HARNESS | D33: High-voltage harness | E33: 0.01 | F33: HV | G33: C29 original-A allocation | H33: ORIGINAL_A | I33: User-supplied BOM figure (15 labelled items; bibliographic metadata pending) | J33: Kept separate from electronic control | K33: 396 | L33: 396 | M33: 396
A34: JPN | B34: Japan | C34: DRIVE_MOTOR | D34: Drive motor (rear single) | E34: 0.027 | F34: M | G34: C27 explicit input | H34: LEGACY_M | I34: User-supplied BOM figure (15 labelled items; bibliographic metadata pending) | J34: Drive motor | K34: 396 | L34: 396 | M34: 396
A35: JPN | B35: Japan | C35: MCU | D35: MCU (motor controller) | E35: 0.023 | F35: E | G35: C26/C27 item split | H35: LEGACY_C | I35: User-supplied BOM figure (15 labelled items; bibliographic metadata pending) | J35: E/C27 item | K35: 396 | L35: 396 | M35: 396
A36: JPN | B36: Japan | C36: REDUCER | D36: Reducer | E36: 0.009 | F36: M | G36: C27 explicit input | H36: LEGACY_M | I36: User-supplied BOM figure (15 labelled items; bibliographic metadata pending) | J36: Included with the drive system | K36: 396 | L36: 396 | M36: 396
A37: JPN | B37: Japan | C37: OBC | D37: OBC (on-board charger) | E37: 0.006 | F37: E | G37: C26/C27 item split | H37: LEGACY_C | I37: User-supplied BOM figure (15 labelled items; bibliographic metadata pending) | J37: E/C27 item | K37: 396 | L37: 396 | M37: 396
A38: JPN | B38: Japan | C38: DCDC | D38: DCDC (direct current-direct current converter) | E38: 0.004 | F38: E | G38: C26/C27 item split | H38: LEGACY_C | I38: User-supplied BOM figure (15 labelled items; bibliographic metadata pending) | J38: E/C27 item | K38: 396 | L38: 396 | M38: 396
A39: JPN | B39: Japan | C39: PDU | D39: PDU (high-voltage distribution box) | E39: 0.007 | F39: E | G39: C26/C27 item split | H39: LEGACY_C | I39: User-supplied BOM figure (15 labelled items; bibliographic metadata pending) | J39: E/C27 item | K39: 396 | L39: 396 | M39: 396
A40: JPN | B40: Japan | C40: BMS | D40: BMS | E40: 0.011 | F40: E | G40: C26/C27 item split | H40: LEGACY_C | I40: User-supplied BOM figure (15 labelled items; bibliographic metadata pending) | J40: E/C26 item | K40: 396 | L40: 396 | M40: 396
...

Sheet BOM_scenarios
A1: scenario | B1: country_code | C1: country_name | D1: item_count | E1: invalid_share_count | F1: b_T | G1: b_M | H1: b_E | I1: b_I | J1: b_EE | K1: b_HV | L1: b_shared | M1: composition_sum | N1: e_c26_bom_share | O1: e_c27_bom_share | P1: e_c26_weight | Q1: e_c27_weight | R1: e_weight_sum | S1: qa_status | T1: description
A2: BASE_FIGURE_ICIO | B2: CHN | C2: China | D2: =COUNTIF(BOM_raw!$A$2:$A$1001,B2) -> 15 | E2: =COUNTIFS(BOM_raw!$A$2:$A$1001,B2,BOM_raw!$E$2:$E$1001,"<0")+COUNTIFS(BOM_raw!$A$2:$A$1001,B2,BOM_raw!$E$2:$E$1001,">1") -> 0 | F2: =SUMIFS(BOM_raw!$E$2:$E$1001,BOM_raw!$A$2:$A$1001,$B2,BOM_raw!$F$2:$F$1001,"T") -> 0.2605 | G2: =SUMIFS(BOM_raw!$E$2:$E$1001,BOM_raw!$A$2:$A$1001,$B2,BOM_raw!$F$2:$F$1001,"M") -> 0.036 | H2: =SUMIFS(BOM_raw!$E$2:$E$1001,BOM_raw!$A$2:$A$1001,$B2,BOM_raw!$F$2:$F$1001,"E") -> 0.053 | I2: =SUMIFS(BOM_raw!$E$2:$E$1001,BOM_raw!$A$2:$A$1001,$B2,BOM_raw!$F$2:$F$1001,"I") -> 0.059 | J2: =SUMIFS(BOM_raw!$E$2:$E$1001,BOM_raw!$A$2:$A$1001,$B2,BOM_raw!$F$2:$F$1001,"EE") -> 0.103 | K2: =SUMIFS(BOM_raw!$E$2:$E$1001,BOM_raw!$A$2:$A$1001,$B2,BOM_raw!$F$2:$F$1001,"HV") -> 0.01 | L2: =SUMIFS(BOM_raw!$E$2:$E$1001,BOM_raw!$A$2:$A$1001,$B2,BOM_raw!$F$2:$F$1001,"SHARED") -> 0.4785 | M2: =SUM(F2:L2) -> 1 | N2: =SUMIFS(BOM_raw!$E$2:$E$1001,BOM_raw!$A$2:$A$1001,$B2,BOM_raw!$C$2:$C$1001,"BMS")+SUMIFS(BOM_raw!$E$2:$E$1001,BOM_raw!$A$2:$A$1001,$B2,BOM_raw!$C$2:$C$1001,"VCU") -> 0.013 | O2: =SUMIFS(BOM_raw!$E$2:$E$1001,BOM_raw!$A$2:$A$1001,$B2,BOM_raw!$C$2:$C$1001,"MCU")+SUMIFS(BOM_raw!$E$2:$E$1001,BOM_raw!$A$2:$A$1001,$B2,BOM_raw!$C$2:$C$1001,"OBC")+SUMIFS(BOM_raw!$E$2:$E$1001,BOM_raw!$A$2:$A$1001,$B2,BOM_raw!$C$2:$C$1001,"DCDC")+SUMIFS(BOM_raw!$E$2:$E$1001,BOM_raw!$A$2:$A$1001,$B2,BOM_raw!$C$2:$C$1001,"PDU") -> 0.04 | P2: =IF(H2=0,0,N2/H2) -> 0.24528302 | Q2: =IF(H2=0,0,O2/H2) -> 0.75471698 | R2: =P2+Q2 -> 1 | S2: =IF(AND(D2=15,E2=0,ABS(M2-1)<0.0000001,ABS(N2+O2-H2)<0.0000001,ABS(R2-1)<0.0000001),"PASS","FAIL") -> PASS | T2: CHN profile; formula-derived from BOM_raw. Exact ISO3 match takes priority; otherwise the R model uses OTHERS.
A3: BASE_FIGURE_ICIO | B3: DEU | C3: Germany | D3: =COUNTIF(BOM_raw!$A$2:$A$1001,B3) -> 15 | E3: =COUNTIFS(BOM_raw!$A$2:$A$1001,B3,BOM_raw!$E$2:$E$1001,"<0")+COUNTIFS(BOM_raw!$A$2:$A$1001,B3,BOM_raw!$E$2:$E$1001,">1") -> 0 | F3: =SUMIFS(BOM_raw!$E$2:$E$1001,BOM_raw!$A$2:$A$1001,$B3,BOM_raw!$F$2:$F$1001,"T") -> 0.2976 | G3: =SUMIFS(BOM_raw!$E$2:$E$1001,BOM_raw!$A$2:$A$1001,$B3,BOM_raw!$F$2:$F$1001,"M") -> 0.036 | H3: =SUMIFS(BOM_raw!$E$2:$E$1001,BOM_raw!$A$2:$A$1001,$B3,BOM_raw!$F$2:$F$1001,"E") -> 0.053 | I3: =SUMIFS(BOM_raw!$E$2:$E$1001,BOM_raw!$A$2:$A$1001,$B3,BOM_raw!$F$2:$F$1001,"I") -> 0.059 | J3: =SUMIFS(BOM_raw!$E$2:$E$1001,BOM_raw!$A$2:$A$1001,$B3,BOM_raw!$F$2:$F$1001,"EE") -> 0.103 | K3: =SUMIFS(BOM_raw!$E$2:$E$1001,BOM_raw!$A$2:$A$1001,$B3,BOM_raw!$F$2:$F$1001,"HV") -> 0.01 | L3: =SUMIFS(BOM_raw!$E$2:$E$1001,BOM_raw!$A$2:$A$1001,$B3,BOM_raw!$F$2:$F$1001,"SHARED") -> 0.4414 | M3: =SUM(F3:L3) -> 1 | N3: =SUMIFS(BOM_raw!$E$2:$E$1001,BOM_raw!$A$2:$A$1001,$B3,BOM_raw!$C$2:$C$1001,"BMS")+SUMIFS(BOM_raw!$E$2:$E$1001,BOM_raw!$A$2:$A$1001,$B3,BOM_raw!$C$2:$C$1001,"VCU") -> 0.013 | O3: =SUMIFS(BOM_raw!$E$2:$E$1001,BOM_raw!$A$2:$A$1001,$B3,BOM_raw!$C$2:$C$1001,"MCU")+SUMIFS(BOM_raw!$E$2:$E$1001,BOM_raw!$A$2:$A$1001,$B3,BOM_raw!$C$2:$C$1001,"OBC")+SUMIFS(BOM_raw!$E$2:$E$1001,BOM_raw!$A$2:$A$1001,$B3,BOM_raw!$C$2:$C$1001,"DCDC")+SUMIFS(BOM_raw!$E$2:$E$1001,BOM_raw!$A$2:$A$1001,$B3,BOM_raw!$C$2:$C$1001,"PDU") -> 0.04 | P3: =IF(H3=0,0,N3/H3) -> 0.24528302 | Q3: =IF(H3=0,0,O3/H3) -> 0.75471698 | R3: =P3+Q3 -> 1 | S3: =IF(AND(D3=15,E3=0,ABS(M3-1)<0.0000001,ABS(N3+O3-H3)<0.0000001,ABS(R3-1)<0.0000001),"PASS","FAIL") -> PASS | T3: DEU profile; formula-derived from BOM_raw. Exact ISO3 match takes priority; otherwise the R model uses OTHERS.
A4: BASE_FIGURE_ICIO | B4: JPN | C4: Japan | D4: =COUNTIF(BOM_raw!$A$2:$A$1001,B4) -> 15 | E4: =COUNTIFS(BOM_raw!$A$2:$A$1001,B4,BOM_raw!$E$2:$E$1001,"<0")+COUNTIFS(BOM_raw!$A$2:$A$1001,B4,BOM_raw!$E$2:$E$1001,">1") -> 0 | F4: =SUMIFS(BOM_raw!$E$2:$E$1001,BOM_raw!$A$2:$A$1001,$B4,BOM_raw!$F$2:$F$1001,"T") -> 0.23335 | G4: =SUMIFS(BOM_raw!$E$2:$E$1001,BOM_raw!$A$2:$A$1001,$B4,BOM_raw!$F$2:$F$1001,"M") -> 0.036 | H4: =SUMIFS(BOM_raw!$E$2:$E$1001,BOM_raw!$A$2:$A$1001,$B4,BOM_raw!$F$2:$F$1001,"E") -> 0.053 | I4: =SUMIFS(BOM_raw!$E$2:$E$1001,BOM_raw!$A$2:$A$1001,$B4,BOM_raw!$F$2:$F$1001,"I") -> 0.059 | J4: =SUMIFS(BOM_raw!$E$2:$E$1001,BOM_raw!$A$2:$A$1001,$B4,BOM_raw!$F$2:$F$1001,"EE") -> 0.103 | K4: =SUMIFS(BOM_raw!$E$2:$E$1001,BOM_raw!$A$2:$A$1001,$B4,BOM_raw!$F$2:$F$1001,"HV") -> 0.01 | L4: =SUMIFS(BOM_raw!$E$2:$E$1001,BOM_raw!$A$2:$A$1001,$B4,BOM_raw!$F$2:$F$1001,"SHARED") -> 0.50565 | M4: =SUM(F4:L4) -> 1 | N4: =SUMIFS(BOM_raw!$E$2:$E$1001,BOM_raw!$A$2:$A$1001,$B4,BOM_raw!$C$2:$C$1001,"BMS")+SUMIFS(BOM_raw!$E$2:$E$1001,BOM_raw!$A$2:$A$1001,$B4,BOM_raw!$C$2:$C$1001,"VCU") -> 0.013 | O4: =SUMIFS(BOM_raw!$E$2:$E$1001,BOM_raw!$A$2:$A$1001,$B4,BOM_raw!$C$2:$C$1001,"MCU")+SUMIFS(BOM_raw!$E$2:$E$1001,BOM_raw!$A$2:$A$1001,$B4,BOM_raw!$C$2:$C$1001,"OBC")+SUMIFS(BOM_raw!$E$2:$E$1001,BOM_raw!$A$2:$A$1001,$B4,BOM_raw!$C$2:$C$1001,"DCDC")+SUMIFS(BOM_raw!$E$2:$E$1001,BOM_raw!$A$2:$A$1001,$B4,BOM_raw!$C$2:$C$1001,"PDU") -> 0.04 | P4: =IF(H4=0,0,N4/H4) -> 0.24528302 | Q4: =IF(H4=0,0,O4/H4) -> 0.75471698 | R4: =P4+Q4 -> 1 | S4: =IF(AND(D4=15,E4=0,ABS(M4-1)<0.0000001,ABS(N4+O4-H4)<0.0000001,ABS(R4-1)<0.0000001),"PASS","FAIL") -> PASS | T4: JPN profile; formula-derived from BOM_raw. Exact ISO3 match takes priority; otherwise the R model uses OTHERS.
A5: BASE_FIGURE_ICIO | B5: KOR | C5: South Korea | D5: =COUNTIF(BOM_raw!$A$2:$A$1001,B5) -> 15 | E5: =COUNTIFS(BOM_raw!$A$2:$A$1001,B5,BOM_raw!$E$2:$E$1001,"<0")+COUNTIFS(BOM_raw!$A$2:$A$1001,B5,BOM_raw!$E$2:$E$1001,">1") -> 0 | F5: =SUMIFS(BOM_raw!$E$2:$E$1001,BOM_raw!$A$2:$A$1001,$B5,BOM_raw!$F$2:$F$1001,"T") -> 0.3316 | G5: =SUMIFS(BOM_raw!$E$2:$E$1001,BOM_raw!$A$2:$A$1001,$B5,BOM_raw!$F$2:$F$1001,"M") -> 0.036 | H5: =SUMIFS(BOM_raw!$E$2:$E$1001,BOM_raw!$A$2:$A$1001,$B5,BOM_raw!$F$2:$F$1001,"E") -> 0.053 | I5: =SUMIFS(BOM_raw!$E$2:$E$1001,BOM_raw!$A$2:$A$1001,$B5,BOM_raw!$F$2:$F$1001,"I") -> 0.059 | J5: =SUMIFS(BOM_raw!$E$2:$E$1001,BOM_raw!$A$2:$A$1001,$B5,BOM_raw!$F$2:$F$1001,"EE") -> 0.103 | K5: =SUMIFS(BOM_raw!$E$2:$E$1001,BOM_raw!$A$2:$A$1001,$B5,BOM_raw!$F$2:$F$1001,"HV") -> 0.01 | L5: =SUMIFS(BOM_raw!$E$2:$E$1001,BOM_raw!$A$2:$A$1001,$B5,BOM_raw!$F$2:$F$1001,"SHARED") -> 0.4074 | M5: =SUM(F5:L5) -> 1 | N5: =SUMIFS(BOM_raw!$E$2:$E$1001,BOM_raw!$A$2:$A$1001,$B5,BOM_raw!$C$2:$C$1001,"BMS")+SUMIFS(BOM_raw!$E$2:$E$1001,BOM_raw!$A$2:$A$1001,$B5,BOM_raw!$C$2:$C$1001,"VCU") -> 0.013 | O5: =SUMIFS(BOM_raw!$E$2:$E$1001,BOM_raw!$A$2:$A$1001,$B5,BOM_raw!$C$2:$C$1001,"MCU")+SUMIFS(BOM_raw!$E$2:$E$1001,BOM_raw!$A$2:$A$1001,$B5,BOM_raw!$C$2:$C$1001,"OBC")+SUMIFS(BOM_raw!$E$2:$E$1001,BOM_raw!$A$2:$A$1001,$B5,BOM_raw!$C$2:$C$1001,"DCDC")+SUMIFS(BOM_raw!$E$2:$E$1001,BOM_raw!$A$2:$A$1001,$B5,BOM_raw!$C$2:$C$1001,"PDU") -> 0.04 | P5: =IF(H5=0,0,N5/H5) -> 0.24528302 | Q5: =IF(H5=0,0,O5/H5) -> 0.75471698 | R5: =P5+Q5 -> 1 | S5: =IF(AND(D5=15,E5=0,ABS(M5-1)<0.0000001,ABS(N5+O5-H5)<0.0000001,ABS(R5-1)<0.0000001),"PASS","FAIL") -> PASS | T5: KOR profile; formula-derived from BOM_raw. Exact ISO3 match takes priority; otherwise the R model uses OTHERS.
A6: BASE_FIGURE_ICIO | B6: MEX | C6: Mexico | D6: =COUNTIF(BOM_raw!$A$2:$A$1001,B6) -> 15 | E6: =COUNTIFS(BOM_raw!$A$2:$A$1001,B6,BOM_raw!$E$2:$E$1001,"<0")+COUNTIFS(BOM_raw!$A$2:$A$1001,B6,BOM_raw!$E$2:$E$1001,">1") -> 0 | F6: =SUMIFS(BOM_raw!$E$2:$E$1001,BOM_raw!$A$2:$A$1001,$B6,BOM_raw!$F$2:$F$1001,"T") -> 0.2969 | G6: =SUMIFS(BOM_raw!$E$2:$E$1001,BOM_raw!$A$2:$A$1001,$B6,BOM_raw!$F$2:$F$1001,"M") -> 0.036 | H6: =SUMIFS(BOM_raw!$E$2:$E$1001,BOM_raw!$A$2:$A$1001,$B6,BOM_raw!$F$2:$F$1001,"E") -> 0.053 | I6: =SUMIFS(BOM_raw!$E$2:$E$1001,BOM_raw!$A$2:$A$1001,$B6,BOM_raw!$F$2:$F$1001,"I") -> 0.059 | J6: =SUMIFS(BOM_raw!$E$2:$E$1001,BOM_raw!$A$2:$A$1001,$B6,BOM_raw!$F$2:$F$1001,"EE") -> 0.103 | K6: =SUMIFS(BOM_raw!$E$2:$E$1001,BOM_raw!$A$2:$A$1001,$B6,BOM_raw!$F$2:$F$1001,"HV") -> 0.01 | L6: =SUMIFS(BOM_raw!$E$2:$E$1001,BOM_raw!$A$2:$A$1001,$B6,BOM_raw!$F$2:$F$1001,"SHARED") -> 0.4421 | M6: =SUM(F6:L6) -> 1 | N6: =SUMIFS(BOM_raw!$E$2:$E$1001,BOM_raw!$A$2:$A$1001,$B6,BOM_raw!$C$2:$C$1001,"BMS")+SUMIFS(BOM_raw!$E$2:$E$1001,BOM_raw!$A$2:$A$1001,$B6,BOM_raw!$C$2:$C$1001,"VCU") -> 0.013 | O6: =SUMIFS(BOM_raw!$E$2:$E$1001,BOM_raw!$A$2:$A$1001,$B6,BOM_raw!$C$2:$C$1001,"MCU")+SUMIFS(BOM_raw!$E$2:$E$1001,BOM_raw!$A$2:$A$1001,$B6,BOM_raw!$C$2:$C$1001,"OBC")+SUMIFS(BOM_raw!$E$2:$E$1001,BOM_raw!$A$2:$A$1001,$B6,BOM_raw!$C$2:$C$1001,"DCDC")+SUMIFS(BOM_raw!$E$2:$E$1001,BOM_raw!$A$2:$A$1001,$B6,BOM_raw!$C$2:$C$1001,"PDU") -> 0.04 | P6: =IF(H6=0,0,N6/H6) -> 0.24528302 | Q6: =IF(H6=0,0,O6/H6) -> 0.75471698 | R6: =P6+Q6 -> 1 | S6: =IF(AND(D6=15,E6=0,ABS(M6-1)<0.0000001,ABS(N6+O6-H6)<0.0000001,ABS(R6-1)<0.0000001),"PASS","FAIL") -> PASS | T6: MEX profile; formula-derived from BOM_raw. Exact ISO3 match takes priority; otherwise the R model uses OTHERS.
A7: BASE_FIGURE_ICIO | B7: USA | C7: United States | D7: =COUNTIF(BOM_raw!$A$2:$A$1001,B7) -> 15 | E7: =COUNTIFS(BOM_raw!$A$2:$A$1001,B7,BOM_raw!$E$2:$E$1001,"<0")+COUNTIFS(BOM_raw!$A$2:$A$1001,B7,BOM_raw!$E$2:$E$1001,">1") -> 0 | F7: =SUMIFS(BOM_raw!$E$2:$E$1001,BOM_raw!$A$2:$A$1001,$B7,BOM_raw!$F$2:$F$1001,"T") -> 0.3075 | G7: =SUMIFS(BOM_raw!$E$2:$E$1001,BOM_raw!$A$2:$A$1001,$B7,BOM_raw!$F$2:$F$1001,"M") -> 0.036 | H7: =SUMIFS(BOM_raw!$E$2:$E$1001,BOM_raw!$A$2:$A$1001,$B7,BOM_raw!$F$2:$F$1001,"E") -> 0.053 | I7: =SUMIFS(BOM_raw!$E$2:$E$1001,BOM_raw!$A$2:$A$1001,$B7,BOM_raw!$F$2:$F$1001,"I") -> 0.059 | J7: =SUMIFS(BOM_raw!$E$2:$E$1001,BOM_raw!$A$2:$A$1001,$B7,BOM_raw!$F$2:$F$1001,"EE") -> 0.103 | K7: =SUMIFS(BOM_raw!$E$2:$E$1001,BOM_raw!$A$2:$A$1001,$B7,BOM_raw!$F$2:$F$1001,"HV") -> 0.01 | L7: =SUMIFS(BOM_raw!$E$2:$E$1001,BOM_raw!$A$2:$A$1001,$B7,BOM_raw!$F$2:$F$1001,"SHARED") -> 0.4315 | M7: =SUM(F7:L7) -> 1 | N7: =SUMIFS(BOM_raw!$E$2:$E$1001,BOM_raw!$A$2:$A$1001,$B7,BOM_raw!$C$2:$C$1001,"BMS")+SUMIFS(BOM_raw!$E$2:$E$1001,BOM_raw!$A$2:$A$1001,$B7,BOM_raw!$C$2:$C$1001,"VCU") -> 0.013 | O7: =SUMIFS(BOM_raw!$E$2:$E$1001,BOM_raw!$A$2:$A$1001,$B7,BOM_raw!$C$2:$C$1001,"MCU")+SUMIFS(BOM_raw!$E$2:$E$1001,BOM_raw!$A$2:$A$1001,$B7,BOM_raw!$C$2:$C$1001,"OBC")+SUMIFS(BOM_raw!$E$2:$E$1001,BOM_raw!$A$2:$A$1001,$B7,BOM_raw!$C$2:$C$1001,"DCDC")+SUMIFS(BOM_raw!$E$2:$E$1001,BOM_raw!$A$2:$A$1001,$B7,BOM_raw!$C$2:$C$1001,"PDU") -> 0.04 | P7: =IF(H7=0,0,N7/H7) -> 0.24528302 | Q7: =IF(H7=0,0,O7/H7) -> 0.75471698 | R7: =P7+Q7 -> 1 | S7: =IF(AND(D7=15,E7=0,ABS(M7-1)<0.0000001,ABS(N7+O7-H7)<0.0000001,ABS(R7-1)<0.0000001),"PASS","FAIL") -> PASS | T7: USA profile; formula-derived from BOM_raw. Exact ISO3 match takes priority; otherwise the R model uses OTHERS.
A8: BASE_FIGURE_ICIO | B8: OTHERS | C8: All other economies (fallback profile) | D8: =COUNTIF(BOM_raw!$A$2:$A$1001,B8) -> 15 | E8: =COUNTIFS(BOM_raw!$A$2:$A$1001,B8,BOM_raw!$E$2:$E$1001,"<0")+COUNTIFS(BOM_raw!$A$2:$A$1001,B8,BOM_raw!$E$2:$E$1001,">1") -> 0 | F8: =SUMIFS(BOM_raw!$E$2:$E$1001,BOM_raw!$A$2:$A$1001,$B8,BOM_raw!$F$2:$F$1001,"T") -> 0.29 | G8: =SUMIFS(BOM_raw!$E$2:$E$1001,BOM_raw!$A$2:$A$1001,$B8,BOM_raw!$F$2:$F$1001,"M") -> 0.036 | H8: =SUMIFS(BOM_raw!$E$2:$E$1001,BOM_raw!$A$2:$A$1001,$B8,BOM_raw!$F$2:$F$1001,"E") -> 0.053 | I8: =SUMIFS(BOM_raw!$E$2:$E$1001,BOM_raw!$A$2:$A$1001,$B8,BOM_raw!$F$2:$F$1001,"I") -> 0.059 | J8: =SUMIFS(BOM_raw!$E$2:$E$1001,BOM_raw!$A$2:$A$1001,$B8,BOM_raw!$F$2:$F$1001,"EE") -> 0.103 | K8: =SUMIFS(BOM_raw!$E$2:$E$1001,BOM_raw!$A$2:$A$1001,$B8,BOM_raw!$F$2:$F$1001,"HV") -> 0.01 | L8: =SUMIFS(BOM_raw!$E$2:$E$1001,BOM_raw!$A$2:$A$1001,$B8,BOM_raw!$F$2:$F$1001,"SHARED") -> 0.449 | M8: =SUM(F8:L8) -> 1 | N8: =SUMIFS(BOM_raw!$E$2:$E$1001,BOM_raw!$A$2:$A$1001,$B8,BOM_raw!$C$2:$C$1001,"BMS")+SUMIFS(BOM_raw!$E$2:$E$1001,BOM_raw!$A$2:$A$1001,$B8,BOM_raw!$C$2:$C$1001,"VCU") -> 0.013 | O8: =SUMIFS(BOM_raw!$E$2:$E$1001,BOM_raw!$A$2:$A$1001,$B8,BOM_raw!$C$2:$C$1001,"MCU")+SUMIFS(BOM_raw!$E$2:$E$1001,BOM_raw!$A$2:$A$1001,$B8,BOM_raw!$C$2:$C$1001,"OBC")+SUMIFS(BOM_raw!$E$2:$E$1001,BOM_raw!$A$2:$A$1001,$B8,BOM_raw!$C$2:$C$1001,"DCDC")+SUMIFS(BOM_raw!$E$2:$E$1001,BOM_raw!$A$2:$A$1001,$B8,BOM_raw!$C$2:$C$1001,"PDU") -> 0.04 | P8: =IF(H8=0,0,N8/H8) -> 0.24528302 | Q8: =IF(H8=0,0,O8/H8) -> 0.75471698 | R8: =P8+Q8 -> 1 | S8: =IF(AND(D8=15,E8=0,ABS(M8-1)<0.0000001,ABS(N8+O8-H8)<0.0000001,ABS(R8-1)<0.0000001),"PASS","FAIL") -> PASS | T8: OTHERS profile; formula-derived from BOM_raw. Exact ISO3 match takes priority; otherwise the R model uses OTHERS.

Sheet Sector_mapping
A1: Mapping ID | B1: System | C1: ICIO45 sector(s) | D1: Allocation weight | E1: Allocation mode | F1: Origin rule | G1: Basis
A2: BASE_FIGURE_ICIO | B2: T | C2: C27 | D2: 1 | E2: STATIC | F2: LEGACY_T | G2: Battery pack; foreign origins use the retained battery proxy.
A3: BASE_FIGURE_ICIO | B3: M | C3: C27 | D3: 1 | E3: STATIC | F3: LEGACY_M | G3: Drive motor and reducer; foreign origins use the retained motor proxy.
A4: BASE_FIGURE_ICIO | B4: E | C4: C26 | D4: BOM_raw-derived | E4: COUNTRY_BOM | F4: LEGACY_C | G4: Country-specific BMS + VCU share within E.
A5: BASE_FIGURE_ICIO | B5: E | C5: C27 | D5: BOM_raw-derived | E5: COUNTRY_BOM | F5: LEGACY_C | G5: Country-specific MCU + OBC + DCDC + PDU share within E.
A6: BASE_FIGURE_ICIO | B6: I | C6: C26 | D6: 1 | E6: ORIGINAL_A | F6: ORIGINAL_A | G6: C26 slice of the original destination-country C29 input column.
A7: BASE_FIGURE_ICIO | B7: EE | C7: C26|C27|C29 | D7: 1 | E7: ORIGINAL_A | F7: ORIGINAL_A | G7: C26/C27/C29 slices of the original C29 input column.
A8: BASE_FIGURE_ICIO | B8: HV | C8: C29 | D8: 1 | E8: ORIGINAL_A | F8: ORIGINAL_A | G8: C29 slice of the original destination-country C29 input column.
A9: BASE_FIGURE_ICIO | B9: SHARED | C9: ALL | D9: 1 | E9: ORIGINAL_A | F9: ORIGINAL_A | G9: Full original destination-country C29 input column.

Sheet ICIO_intensity
A1: ISO3 | B1: Active C29 | C1: C29 output | D1: Intermediate inputs | E1: u_intermediate | F1: TLS share | G1: VA share | H1: Primary input share (1-u) | I1: ICIO balance | J1: Source/formula | K1: FV VA share
A2: ARG | B2: TRUE | C2: 26022.443 | D2: 18523.66 | E2: 0.711834 | F2: 0.040430305 | G2: 0.28489573 | H2: 0.288166 | I2: 0.99999972 | J2: 2022_SML.csv; u=inputs/OUT; TLS=raw TLS/OUT; VA=1.17*(raw VA/OUT); balance uses raw ICIO shares | K2: 0.24773542
A3: AUS | B3: TRUE | C3: 10356.149 | D3: 6711.6235 | E3: 0.64808101 | F3: 0.0098373343 | G3: 0.39339298 | H3: 0.35191899 | I3: 0.9999992 | J3: 2022_SML.csv; u=inputs/OUT; TLS=raw TLS/OUT; VA=1.17*(raw VA/OUT); balance uses raw ICIO shares | K3: 0.34208085
A4: AUT | B4: TRUE | C4: 18867.448 | D4: 13726.463 | E4: 0.72752092 | F4: 0.032032016 | G4: 0.27651396 | H4: 0.27247908 | I4: 0.99999986 | J4: 2022_SML.csv; u=inputs/OUT; TLS=raw TLS/OUT; VA=1.17*(raw VA/OUT); balance uses raw ICIO shares | K4: 0.24044692
A5: BEL | B5: TRUE | C5: 17076.613 | D5: 13850.972 | E5: 0.81110764 | F5: 0.048382169 | G5: 0.16158645 | H5: 0.18889236 | I5: 0.99999976 | J5: 2022_SML.csv; u=inputs/OUT; TLS=raw TLS/OUT; VA=1.17*(raw VA/OUT); balance uses raw ICIO shares | K5: 0.14050996
A6: BGD | B6: TRUE | C6: 237.1202 | D6: 154.3647 | E6: 0.65099768 | F6: 0.0176012 | G6: 0.38107346 | H6: 0.34900232 | I6: 0.99996711 | J6: 2022_SML.csv; u=inputs/OUT; TLS=raw TLS/OUT; VA=1.17*(raw VA/OUT); balance uses raw ICIO shares | K6: 0.33136823
A7: BGR | B7: TRUE | C7: 2326.7253 | D7: 1808.9522 | E7: 0.77746703 | F7: 0.031275286 | G7: 0.21994268 | H7: 0.22253297 | I7: 0.99999682 | J7: 2022_SML.csv; u=inputs/OUT; TLS=raw TLS/OUT; VA=1.17*(raw VA/OUT); balance uses raw ICIO shares | K7: 0.19125451
A8: BLR | B8: TRUE | C8: 3008.9881 | D8: 1734.2624 | E8: 0.57636067 | F8: 0.030855622 | G8: 0.45169859 | H8: 0.42363933 | I8: 0.99999767 | J8: 2022_SML.csv; u=inputs/OUT; TLS=raw TLS/OUT; VA=1.17*(raw VA/OUT); balance uses raw ICIO shares | K8: 0.39278138
A9: BRA | B9: TRUE | C9: 80446.521 | D9: 65304.367 | E9: 0.81177367 | F9: 0.043983444 | G9: 0.16587923 | H9: 0.18822633 | I9: 0.99999992 | J9: 2022_SML.csv; u=inputs/OUT; TLS=raw TLS/OUT; VA=1.17*(raw VA/OUT); balance uses raw ICIO shares | K9: 0.14424281
A10: BRN | B10: FALSE | C10: 0 | D10: 0 | E10: 0 | F10: 0 | G10: 0 | H10: 0 | I10: 0 | J10: 2022_SML.csv; u=inputs/OUT; TLS=raw TLS/OUT; VA=1.17*(raw VA/OUT); balance uses raw ICIO shares | K10: 0
A11: CAN | B11: TRUE | C11: 58839.515 | D11: 46596.765 | E11: 0.7919298 | F11: 0.028941943 | G11: 0.20599735 | H11: 0.2080702 | I11: 0.99999987 | J11: 2022_SML.csv; u=inputs/OUT; TLS=raw TLS/OUT; VA=1.17*(raw VA/OUT); balance uses raw ICIO shares | K11: 0.17912813
A12: CHE | B12: TRUE | C12: 1971.0051 | D12: 1314.2006 | E12: 0.66676672 | F12: 0.023638701 | G12: 0.35603009 | H12: 0.33323328 | I12: 0.9999968 | J12: 2022_SML.csv; u=inputs/OUT; TLS=raw TLS/OUT; VA=1.17*(raw VA/OUT); balance uses raw ICIO shares | K12: 0.30959139
A13: CHL | B13: FALSE | C13: 0 | D13: 0 | E13: 0 | F13: 0 | G13: 0 | H13: 0 | I13: 0 | J13: 2022_SML.csv; u=inputs/OUT; TLS=raw TLS/OUT; VA=1.17*(raw VA/OUT); balance uses raw ICIO shares | K13: 0
... A78: ROW | B78: TRUE | C78: 85511.034 | D78: 56691.416 | E78: 0.66297193 | F78: 0.031428801 | G78: 0.35143873 | H78: 0.33702807 | I78: 0.99999963 | J78: 2022_SML.csv; u=inputs/OUT; TLS=raw TLS/OUT; VA=1.17*(raw VA/OUT); balance uses raw ICIO shares | K78: 0.30559889

Sheet Beta_derived
A1: scenario | B1: ISO3 | C1: bom_profile_used | D1: profile_match_status | E1: Active C29 | F1: intermediate_input_share | G1: Value-added and TLS share (1-u) | H1: b_T | I1: b_M | J1: b_E | K1: b_I | L1: b_EE | M1: b_HV | N1: b_shared | O1: composition_sum | P1: BOM budget rho | Q1: beta_T | R1: beta_M | S1: beta_E | T1: beta_I | U1: beta_EE | V1: beta_HV | W1: beta_shared | X1: beta_sum | Y1: intermediate_balance | Z1: full_column_balance | AA1: QA status | AB1: Source
A2: ="BASE_FIGURE_ICIO" -> BASE_FIGURE_ICIO | B2: =ICIO_intensity!A2 -> ARG | C2: =IF(COUNTIF(BOM_raw!$A$2:$A$1001,B2)>0,B2,"OTHERS") -> OTHERS | D2: =IF(C2=B2,"EXACT","OTHERS_FALLBACK") -> OTHERS_FALLBACK | E2: =ICIO_intensity!B2 -> TRUE | F2: =ICIO_intensity!E2 -> 0.711834 | G2: =ICIO_intensity!H2 -> 0.288166 | H2: =SUMIFS(BOM_raw!$E$2:$E$1001,BOM_raw!$A$2:$A$1001,$C2,BOM_raw!$F$2:$F$1001,"T") -> 0.29 | I2: =SUMIFS(BOM_raw!$E$2:$E$1001,BOM_raw!$A$2:$A$1001,$C2,BOM_raw!$F$2:$F$1001,"M") -> 0.036 | J2: =SUMIFS(BOM_raw!$E$2:$E$1001,BOM_raw!$A$2:$A$1001,$C2,BOM_raw!$F$2:$F$1001,"E") -> 0.053 | K2: =SUMIFS(BOM_raw!$E$2:$E$1001,BOM_raw!$A$2:$A$1001,$C2,BOM_raw!$F$2:$F$1001,"I") -> 0.059 | L2: =SUMIFS(BOM_raw!$E$2:$E$1001,BOM_raw!$A$2:$A$1001,$C2,BOM_raw!$F$2:$F$1001,"EE") -> 0.103 | M2: =SUMIFS(BOM_raw!$E$2:$E$1001,BOM_raw!$A$2:$A$1001,$C2,BOM_raw!$F$2:$F$1001,"HV") -> 0.01 | N2: =SUMIFS(BOM_raw!$E$2:$E$1001,BOM_raw!$A$2:$A$1001,$C2,BOM_raw!$F$2:$F$1001,"SHARED") -> 0.449 | O2: =SUM(H2:N2) -> 1 | P2: =IF(E2,F2,0) -> 0.711834 | Q2: =P2*H2 -> 0.20643186 | R2: =P2*I2 -> 0.025626024 | S2: =P2*J2 -> 0.037727202 | T2: =P2*K2 -> 0.041998206 | U2: =P2*L2 -> 0.073318902 | V2: =P2*M2 -> 0.00711834 | W2: =P2*N2 -> 0.31961347 | X2: =SUM(Q2:W2) -> 0.711834 | Y2: =X2-F2 -> 0 | Z2: =X2+G2 -> 1 | AA2: =IF(E2,IF(AND(ABS(O2-1)<0.0000001,ABS(Y2)<0.0000001,ABS(Z2-1)<0.0000001),"PASS","FAIL"),"INACTIVE") -> PASS | AB2: BOM_raw + ICIO_intensity; exact ISO3 or OTHERS fallback
A3: ="BASE_FIGURE_ICIO" -> BASE_FIGURE_ICIO | B3: =ICIO_intensity!A3 -> AUS | C3: =IF(COUNTIF(BOM_raw!$A$2:$A$1001,B3)>0,B3,"OTHERS") -> OTHERS | D3: =IF(C3=B3,"EXACT","OTHERS_FALLBACK") -> OTHERS_FALLBACK | E3: =ICIO_intensity!B3 -> TRUE | F3: =ICIO_intensity!E3 -> 0.64808101 | G3: =ICIO_intensity!H3 -> 0.35191899 | H3: =SUMIFS(BOM_raw!$E$2:$E$1001,BOM_raw!$A$2:$A$1001,$C3,BOM_raw!$F$2:$F$1001,"T") -> 0.29 | I3: =SUMIFS(BOM_raw!$E$2:$E$1001,BOM_raw!$A$2:$A$1001,$C3,BOM_raw!$F$2:$F$1001,"M") -> 0.036 | J3: =SUMIFS(BOM_raw!$E$2:$E$1001,BOM_raw!$A$2:$A$1001,$C3,BOM_raw!$F$2:$F$1001,"E") -> 0.053 | K3: =SUMIFS(BOM_raw!$E$2:$E$1001,BOM_raw!$A$2:$A$1001,$C3,BOM_raw!$F$2:$F$1001,"I") -> 0.059 | L3: =SUMIFS(BOM_raw!$E$2:$E$1001,BOM_raw!$A$2:$A$1001,$C3,BOM_raw!$F$2:$F$1001,"EE") -> 0.103 | M3: =SUMIFS(BOM_raw!$E$2:$E$1001,BOM_raw!$A$2:$A$1001,$C3,BOM_raw!$F$2:$F$1001,"HV") -> 0.01 | N3: =SUMIFS(BOM_raw!$E$2:$E$1001,BOM_raw!$A$2:$A$1001,$C3,BOM_raw!$F$2:$F$1001,"SHARED") -> 0.449 | O3: =SUM(H3:N3) -> 1 | P3: =IF(E3,F3,0) -> 0.64808101 | Q3: =P3*H3 -> 0.18794349 | R3: =P3*I3 -> 0.023330916 | S3: =P3*J3 -> 0.034348294 | T3: =P3*K3 -> 0.03823678 | U3: =P3*L3 -> 0.066752344 | V3: =P3*M3 -> 0.0064808101 | W3: =P3*N3 -> 0.29098837 | X3: =SUM(Q3:W3) -> 0.64808101 | Y3: =X3-F3 -> 0 | Z3: =X3+G3 -> 1 | AA3: =IF(E3,IF(AND(ABS(O3-1)<0.0000001,ABS(Y3)<0.0000001,ABS(Z3-1)<0.0000001),"PASS","FAIL"),"INACTIVE") -> PASS | AB3: BOM_raw + ICIO_intensity; exact ISO3 or OTHERS fallback
A4: ="BASE_FIGURE_ICIO" -> BASE_FIGURE_ICIO | B4: =ICIO_intensity!A4 -> AUT | C4: =IF(COUNTIF(BOM_raw!$A$2:$A$1001,B4)>0,B4,"OTHERS") -> OTHERS | D4: =IF(C4=B4,"EXACT","OTHERS_FALLBACK") -> OTHERS_FALLBACK | E4: =ICIO_intensity!B4 -> TRUE | F4: =ICIO_intensity!E4 -> 0.72752092 | G4: =ICIO_intensity!H4 -> 0.27247908 | H4: =SUMIFS(BOM_raw!$E$2:$E$1001,BOM_raw!$A$2:$A$1001,$C4,BOM_raw!$F$2:$F$1001,"T") -> 0.29 | I4: =SUMIFS(BOM_raw!$E$2:$E$1001,BOM_raw!$A$2:$A$1001,$C4,BOM_raw!$F$2:$F$1001,"M") -> 0.036 | J4: =SUMIFS(BOM_raw!$E$2:$E$1001,BOM_raw!$A$2:$A$1001,$C4,BOM_raw!$F$2:$F$1001,"E") -> 0.053 | K4: =SUMIFS(BOM_raw!$E$2:$E$1001,BOM_raw!$A$2:$A$1001,$C4,BOM_raw!$F$2:$F$1001,"I") -> 0.059 | L4: =SUMIFS(BOM_raw!$E$2:$E$1001,BOM_raw!$A$2:$A$1001,$C4,BOM_raw!$F$2:$F$1001,"EE") -> 0.103 | M4: =SUMIFS(BOM_raw!$E$2:$E$1001,BOM_raw!$A$2:$A$1001,$C4,BOM_raw!$F$2:$F$1001,"HV") -> 0.01 | N4: =SUMIFS(BOM_raw!$E$2:$E$1001,BOM_raw!$A$2:$A$1001,$C4,BOM_raw!$F$2:$F$1001,"SHARED") -> 0.449 | O4: =SUM(H4:N4) -> 1 | P4: =IF(E4,F4,0) -> 0.72752092 | Q4: =P4*H4 -> 0.21098107 | R4: =P4*I4 -> 0.026190753 | S4: =P4*J4 -> 0.038558609 | T4: =P4*K4 -> 0.042923734 | U4: =P4*L4 -> 0.074934654 | V4: =P4*M4 -> 0.0072752092 | W4: =P4*N4 -> 0.32665689 | X4: =SUM(Q4:W4) -> 0.72752092 | Y4: =X4-F4 -> 0 | Z4: =X4+G4 -> 1 | AA4: =IF(E4,IF(AND(ABS(O4-1)<0.0000001,ABS(Y4)<0.0000001,ABS(Z4-1)<0.0000001),"PASS","FAIL"),"INACTIVE") -> PASS | AB4: BOM_raw + ICIO_intensity; exact ISO3 or OTHERS fallback
A5: ="BASE_FIGURE_ICIO" -> BASE_FIGURE_ICIO | B5: =ICIO_intensity!A5 -> BEL | C5: =IF(COUNTIF(BOM_raw!$A$2:$A$1001,B5)>0,B5,"OTHERS") -> OTHERS | D5: =IF(C5=B5,"EXACT","OTHERS_FALLBACK") -> OTHERS_FALLBACK | E5: =ICIO_intensity!B5 -> TRUE | F5: =ICIO_intensity!E5 -> 0.81110764 | G5: =ICIO_intensity!H5 -> 0.18889236 | H5: =SUMIFS(BOM_raw!$E$2:$E$1001,BOM_raw!$A$2:$A$1001,$C5,BOM_raw!$F$2:$F$1001,"T") -> 0.29 | I5: =SUMIFS(BOM_raw!$E$2:$E$1001,BOM_raw!$A$2:$A$1001,$C5,BOM_raw!$F$2:$F$1001,"M") -> 0.036 | J5: =SUMIFS(BOM_raw!$E$2:$E$1001,BOM_raw!$A$2:$A$1001,$C5,BOM_raw!$F$2:$F$1001,"E") -> 0.053 | K5: =SUMIFS(BOM_raw!$E$2:$E$1001,BOM_raw!$A$2:$A$1001,$C5,BOM_raw!$F$2:$F$1001,"I") -> 0.059 | L5: =SUMIFS(BOM_raw!$E$2:$E$1001,BOM_raw!$A$2:$A$1001,$C5,BOM_raw!$F$2:$F$1001,"EE") -> 0.103 | M5: =SUMIFS(BOM_raw!$E$2:$E$1001,BOM_raw!$A$2:$A$1001,$C5,BOM_raw!$F$2:$F$1001,"HV") -> 0.01 | N5: =SUMIFS(BOM_raw!$E$2:$E$1001,BOM_raw!$A$2:$A$1001,$C5,BOM_raw!$F$2:$F$1001,"SHARED") -> 0.449 | O5: =SUM(H5:N5) -> 1 | P5: =IF(E5,F5,0) -> 0.81110764 | Q5: =P5*H5 -> 0.23522121 | R5: =P5*I5 -> 0.029199875 | S5: =P5*J5 -> 0.042988705 | T5: =P5*K5 -> 0.047855351 | U5: =P5*L5 -> 0.083544086 | V5: =P5*M5 -> 0.0081110764 | W5: =P5*N5 -> 0.36418733 | X5: =SUM(Q5:W5) -> 0.81110764 | Y5: =X5-F5 -> 0 | Z5: =X5+G5 -> 1 | AA5: =IF(E5,IF(AND(ABS(O5-1)<0.0000001,ABS(Y5)<0.0000001,ABS(Z5-1)<0.0000001),"PASS","FAIL"),"INACTIVE") -> PASS | AB5: BOM_raw + ICIO_intensity; exact ISO3 or OTHERS fallback
A6: ="BASE_FIGURE_ICIO" -> BASE_FIGURE_ICIO | B6: =ICIO_intensity!A6 -> BGD | C6: =IF(COUNTIF(BOM_raw!$A$2:$A$1001,B6)>0,B6,"OTHERS") -> OTHERS | D6: =IF(C6=B6,"EXACT","OTHERS_FALLBACK") -> OTHERS_FALLBACK | E6: =ICIO_intensity!B6 -> TRUE | F6: =ICIO_intensity!E6 -> 0.65099768 | G6: =ICIO_intensity!H6 -> 0.34900232 | H6: =SUMIFS(BOM_raw!$E$2:$E$1001,BOM_raw!$A$2:$A$1001,$C6,BOM_raw!$F$2:$F$1001,"T") -> 0.29 | I6: =SUMIFS(BOM_raw!$E$2:$E$1001,BOM_raw!$A$2:$A$1001,$C6,BOM_raw!$F$2:$F$1001,"M") -> 0.036 | J6: =SUMIFS(BOM_raw!$E$2:$E$1001,BOM_raw!$A$2:$A$1001,$C6,BOM_raw!$F$2:$F$1001,"E") -> 0.053 | K6: =SUMIFS(BOM_raw!$E$2:$E$1001,BOM_raw!$A$2:$A$1001,$C6,BOM_raw!$F$2:$F$1001,"I") -> 0.059 | L6: =SUMIFS(BOM_raw!$E$2:$E$1001,BOM_raw!$A$2:$A$1001,$C6,BOM_raw!$F$2:$F$1001,"EE") -> 0.103 | M6: =SUMIFS(BOM_raw!$E$2:$E$1001,BOM_raw!$A$2:$A$1001,$C6,BOM_raw!$F$2:$F$1001,"HV") -> 0.01 | N6: =SUMIFS(BOM_raw!$E$2:$E$1001,BOM_raw!$A$2:$A$1001,$C6,BOM_raw!$F$2:$F$1001,"SHARED") -> 0.449 | O6: =SUM(H6:N6) -> 1 | P6: =IF(E6,F6,0) -> 0.65099768 | Q6: =P6*H6 -> 0.18878933 | R6: =P6*I6 -> 0.023435916 | S6: =P6*J6 -> 0.034502877 | T6: =P6*K6 -> 0.038408863 | U6: =P6*L6 -> 0.067052761 | V6: =P6*M6 -> 0.0065099768 | W6: =P6*N6 -> 0.29229796 | X6: =SUM(Q6:W6) -> 0.65099768 | Y6: =X6-F6 -> 0 | Z6: =X6+G6 -> 1 | AA6: =IF(E6,IF(AND(ABS(O6-1)<0.0000001,ABS(Y6)<0.0000001,ABS(Z6-1)<0.0000001),"PASS","FAIL"),"INACTIVE") -> PASS | AB6: BOM_raw + ICIO_intensity; exact ISO3 or OTHERS fallback
A7: ="BASE_FIGURE_ICIO" -> BASE_FIGURE_ICIO | B7: =ICIO_intensity!A7 -> BGR | C7: =IF(COUNTIF(BOM_raw!$A$2:$A$1001,B7)>0,B7,"OTHERS") -> OTHERS | D7: =IF(C7=B7,"EXACT","OTHERS_FALLBACK") -> OTHERS_FALLBACK | E7: =ICIO_intensity!B7 -> TRUE | F7: =ICIO_intensity!E7 -> 0.77746703 | G7: =ICIO_intensity!H7 -> 0.22253297 | H7: =SUMIFS(BOM_raw!$E$2:$E$1001,BOM_raw!$A$2:$A$1001,$C7,BOM_raw!$F$2:$F$1001,"T") -> 0.29 | I7: =SUMIFS(BOM_raw!$E$2:$E$1001,BOM_raw!$A$2:$A$1001,$C7,BOM_raw!$F$2:$F$1001,"M") -> 0.036 | J7: =SUMIFS(BOM_raw!$E$2:$E$1001,BOM_raw!$A$2:$A$1001,$C7,BOM_raw!$F$2:$F$1001,"E") -> 0.053 | K7: =SUMIFS(BOM_raw!$E$2:$E$1001,BOM_raw!$A$2:$A$1001,$C7,BOM_raw!$F$2:$F$1001,"I") -> 0.059 | L7: =SUMIFS(BOM_raw!$E$2:$E$1001,BOM_raw!$A$2:$A$1001,$C7,BOM_raw!$F$2:$F$1001,"EE") -> 0.103 | M7: =SUMIFS(BOM_raw!$E$2:$E$1001,BOM_raw!$A$2:$A$1001,$C7,BOM_raw!$F$2:$F$1001,"HV") -> 0.01 | N7: =SUMIFS(BOM_raw!$E$2:$E$1001,BOM_raw!$A$2:$A$1001,$C7,BOM_raw!$F$2:$F$1001,"SHARED") -> 0.449 | O7: =SUM(H7:N7) -> 1 | P7: =IF(E7,F7,0) -> 0.77746703 | Q7: =P7*H7 -> 0.22546544 | R7: =P7*I7 -> 0.027988813 | S7: =P7*J7 -> 0.041205752 | T7: =P7*K7 -> 0.045870555 | U7: =P7*L7 -> 0.080079104 | V7: =P7*M7 -> 0.0077746703 | W7: =P7*N7 -> 0.34908269 | X7: =SUM(Q7:W7) -> 0.77746703 | Y7: =X7-F7 -> 0 | Z7: =X7+G7 -> 1 | AA7: =IF(E7,IF(AND(ABS(O7-1)<0.0000001,ABS(Y7)<0.0000001,ABS(Z7-1)<0.0000001),"PASS","FAIL"),"INACTIVE") -> PASS | AB7: BOM_raw + ICIO_intensity; exact ISO3 or OTHERS fallback
A8: ="BASE_FIGURE_ICIO" -> BASE_FIGURE_ICIO | B8: =ICIO_intensity!A8 -> BLR | C8: =IF(COUNTIF(BOM_raw!$A$2:$A$1001,B8)>0,B8,"OTHERS") -> OTHERS | D8: =IF(C8=B8,"EXACT","OTHERS_FALLBACK") -> OTHERS_FALLBACK | E8: =ICIO_intensity!B8 -> TRUE | F8: =ICIO_intensity!E8 -> 0.57636067 | G8: =ICIO_intensity!H8 -> 0.42363933 | H8: =SUMIFS(BOM_raw!$E$2:$E$1001,BOM_raw!$A$2:$A$1001,$C8,BOM_raw!$F$2:$F$1001,"T") -> 0.29 | I8: =SUMIFS(BOM_raw!$E$2:$E$1001,BOM_raw!$A$2:$A$1001,$C8,BOM_raw!$F$2:$F$1001,"M") -> 0.036 | J8: =SUMIFS(BOM_raw!$E$2:$E$1001,BOM_raw!$A$2:$A$1001,$C8,BOM_raw!$F$2:$F$1001,"E") -> 0.053 | K8: =SUMIFS(BOM_raw!$E$2:$E$1001,BOM_raw!$A$2:$A$1001,$C8,BOM_raw!$F$2:$F$1001,"I") -> 0.059 | L8: =SUMIFS(BOM_raw!$E$2:$E$1001,BOM_raw!$A$2:$A$1001,$C8,BOM_raw!$F$2:$F$1001,"EE") -> 0.103 | M8: =SUMIFS(BOM_raw!$E$2:$E$1001,BOM_raw!$A$2:$A$1001,$C8,BOM_raw!$F$2:$F$1001,"HV") -> 0.01 | N8: =SUMIFS(BOM_raw!$E$2:$E$1001,BOM_raw!$A$2:$A$1001,$C8,BOM_raw!$F$2:$F$1001,"SHARED") -> 0.449 | O8: =SUM(H8:N8) -> 1 | P8: =IF(E8,F8,0) -> 0.57636067 | Q8: =P8*H8 -> 0.16714459 | R8: =P8*I8 -> 0.020748984 | S8: =P8*J8 -> 0.030547116 | T8: =P8*K8 -> 0.03400528 | U8: =P8*L8 -> 0.059365149 | V8: =P8*M8 -> 0.0057636067 | W8: =P8*N8 -> 0.25878594 | X8: =SUM(Q8:W8) -> 0.57636067 | Y8: =X8-F8 -> 0 | Z8: =X8+G8 -> 1 | AA8: =IF(E8,IF(AND(ABS(O8-1)<0.0000001,ABS(Y8)<0.0000001,ABS(Z8-1)<0.0000001),"PASS","FAIL"),"INACTIVE") -> PASS | AB8: BOM_raw + ICIO_intensity; exact ISO3 or OTHERS fallback
A9: ="BASE_FIGURE_ICIO" -> BASE_FIGURE_ICIO | B9: =ICIO_intensity!A9 -> BRA | C9: =IF(COUNTIF(BOM_raw!$A$2:$A$1001,B9)>0,B9,"OTHERS") -> OTHERS | D9: =IF(C9=B9,"EXACT","OTHERS_FALLBACK") -> OTHERS_FALLBACK | E9: =ICIO_intensity!B9 -> TRUE | F9: =ICIO_intensity!E9 -> 0.81177367 | G9: =ICIO_intensity!H9 -> 0.18822633 | H9: =SUMIFS(BOM_raw!$E$2:$E$1001,BOM_raw!$A$2:$A$1001,$C9,BOM_raw!$F$2:$F$1001,"T") -> 0.29 | I9: =SUMIFS(BOM_raw!$E$2:$E$1001,BOM_raw!$A$2:$A$1001,$C9,BOM_raw!$F$2:$F$1001,"M") -> 0.036 | J9: =SUMIFS(BOM_raw!$E$2:$E$1001,BOM_raw!$A$2:$A$1001,$C9,BOM_raw!$F$2:$F$1001,"E") -> 0.053 | K9: =SUMIFS(BOM_raw!$E$2:$E$1001,BOM_raw!$A$2:$A$1001,$C9,BOM_raw!$F$2:$F$1001,"I") -> 0.059 | L9: =SUMIFS(BOM_raw!$E$2:$E$1001,BOM_raw!$A$2:$A$1001,$C9,BOM_raw!$F$2:$F$1001,"EE") -> 0.103 | M9: =SUMIFS(BOM_raw!$E$2:$E$1001,BOM_raw!$A$2:$A$1001,$C9,BOM_raw!$F$2:$F$1001,"HV") -> 0.01 | N9: =SUMIFS(BOM_raw!$E$2:$E$1001,BOM_raw!$A$2:$A$1001,$C9,BOM_raw!$F$2:$F$1001,"SHARED") -> 0.449 | O9: =SUM(H9:N9) -> 1 | P9: =IF(E9,F9,0) -> 0.81177367 | Q9: =P9*H9 -> 0.23541436 | R9: =P9*I9 -> 0.029223852 | S9: =P9*J9 -> 0.043024004 | T9: =P9*K9 -> 0.047894646 | U9: =P9*L9 -> 0.083612688 | V9: =P9*M9 -> 0.0081177367 | W9: =P9*N9 -> 0.36448638 | X9: =SUM(Q9:W9) -> 0.81177367 | Y9: =X9-F9 -> 0 | Z9: =X9+G9 -> 1 | AA9: =IF(E9,IF(AND(ABS(O9-1)<0.0000001,ABS(Y9)<0.0000001,ABS(Z9-1)<0.0000001),"PASS","FAIL"),"INACTIVE") -> PASS | AB9: BOM_raw + ICIO_intensity; exact ISO3 or OTHERS fallback
A10: ="BASE_FIGURE_ICIO" -> BASE_FIGURE_ICIO | B10: =ICIO_intensity!A10 -> BRN | C10: =IF(COUNTIF(BOM_raw!$A$2:$A$1001,B10)>0,B10,"OTHERS") -> OTHERS | D10: =IF(C10=B10,"EXACT","OTHERS_FALLBACK") -> OTHERS_FALLBACK | E10: =ICIO_intensity!B10 -> FALSE | F10: =ICIO_intensity!E10 -> 0 | G10: =ICIO_intensity!H10 -> 0 | H10: =SUMIFS(BOM_raw!$E$2:$E$1001,BOM_raw!$A$2:$A$1001,$C10,BOM_raw!$F$2:$F$1001,"T") -> 0.29 | I10: =SUMIFS(BOM_raw!$E$2:$E$1001,BOM_raw!$A$2:$A$1001,$C10,BOM_raw!$F$2:$F$1001,"M") -> 0.036 | J10: =SUMIFS(BOM_raw!$E$2:$E$1001,BOM_raw!$A$2:$A$1001,$C10,BOM_raw!$F$2:$F$1001,"E") -> 0.053 | K10: =SUMIFS(BOM_raw!$E$2:$E$1001,BOM_raw!$A$2:$A$1001,$C10,BOM_raw!$F$2:$F$1001,"I") -> 0.059 | L10: =SUMIFS(BOM_raw!$E$2:$E$1001,BOM_raw!$A$2:$A$1001,$C10,BOM_raw!$F$2:$F$1001,"EE") -> 0.103 | M10: =SUMIFS(BOM_raw!$E$2:$E$1001,BOM_raw!$A$2:$A$1001,$C10,BOM_raw!$F$2:$F$1001,"HV") -> 0.01 | N10: =SUMIFS(BOM_raw!$E$2:$E$1001,BOM_raw!$A$2:$A$1001,$C10,BOM_raw!$F$2:$F$1001,"SHARED") -> 0.449 | O10: =SUM(H10:N10) -> 1 | P10: =IF(E10,F10,0) -> 0 | Q10: =P10*H10 -> 0 | R10: =P10*I10 -> 0 | S10: =P10*J10 -> 0 | T10: =P10*K10 -> 0 | U10: =P10*L10 -> 0 | V10: =P10*M10 -> 0 | W10: =P10*N10 -> 0 | X10: =SUM(Q10:W10) -> 0 | Y10: =X10-F10 -> 0 | Z10: =X10+G10 -> 0 | AA10: =IF(E10,IF(AND(ABS(O10-1)<0.0000001,ABS(Y10)<0.0000001,ABS(Z10-1)<0.0000001),"PASS","FAIL"),"INACTIVE") -> INACTIVE | AB10: BOM_raw + ICIO_intensity; exact ISO3 or OTHERS fallback
A11: ="BASE_FIGURE_ICIO" -> BASE_FIGURE_ICIO | B11: =ICIO_intensity!A11 -> CAN | C11: =IF(COUNTIF(BOM_raw!$A$2:$A$1001,B11)>0,B11,"OTHERS") -> OTHERS | D11: =IF(C11=B11,"EXACT","OTHERS_FALLBACK") -> OTHERS_FALLBACK | E11: =ICIO_intensity!B11 -> TRUE | F11: =ICIO_intensity!E11 -> 0.7919298 | G11: =ICIO_intensity!H11 -> 0.2080702 | H11: =SUMIFS(BOM_raw!$E$2:$E$1001,BOM_raw!$A$2:$A$1001,$C11,BOM_raw!$F$2:$F$1001,"T") -> 0.29 | I11: =SUMIFS(BOM_raw!$E$2:$E$1001,BOM_raw!$A$2:$A$1001,$C11,BOM_raw!$F$2:$F$1001,"M") -> 0.036 | J11: =SUMIFS(BOM_raw!$E$2:$E$1001,BOM_raw!$A$2:$A$1001,$C11,BOM_raw!$F$2:$F$1001,"E") -> 0.053 | K11: =SUMIFS(BOM_raw!$E$2:$E$1001,BOM_raw!$A$2:$A$1001,$C11,BOM_raw!$F$2:$F$1001,"I") -> 0.059 | L11: =SUMIFS(BOM_raw!$E$2:$E$1001,BOM_raw!$A$2:$A$1001,$C11,BOM_raw!$F$2:$F$1001,"EE") -> 0.103 | M11: =SUMIFS(BOM_raw!$E$2:$E$1001,BOM_raw!$A$2:$A$1001,$C11,BOM_raw!$F$2:$F$1001,"HV") -> 0.01 | N11: =SUMIFS(BOM_raw!$E$2:$E$1001,BOM_raw!$A$2:$A$1001,$C11,BOM_raw!$F$2:$F$1001,"SHARED") -> 0.449 | O11: =SUM(H11:N11) -> 1 | P11: =IF(E11,F11,0) -> 0.7919298 | Q11: =P11*H11 -> 0.22965964 | R11: =P11*I11 -> 0.028509473 | S11: =P11*J11 -> 0.041972279 | T11: =P11*K11 -> 0.046723858 | U11: =P11*L11 -> 0.081568769 | V11: =P11*M11 -> 0.007919298 | W11: =P11*N11 -> 0.35557648 | X11: =SUM(Q11:W11) -> 0.7919298 | Y11: =X11-F11 -> 0 | Z11: =X11+G11 -> 1 | AA11: =IF(E11,IF(AND(ABS(O11-1)<0.0000001,ABS(Y11)<0.0000001,ABS(Z11-1)<0.0000001),"PASS","FAIL"),"INACTIVE") -> PASS | AB11: BOM_raw + ICIO_intensity; exact ISO3 or OTHERS fallback
A12: ="BASE_FIGURE_ICIO" -> BASE_FIGURE_ICIO | B12: =ICIO_intensity!A12 -> CHE | C12: =IF(COUNTIF(BOM_raw!$A$2:$A$1001,B12)>0,B12,"OTHERS") -> OTHERS | D12: =IF(C12=B12,"EXACT","OTHERS_FALLBACK") -> OTHERS_FALLBACK | E12: =ICIO_intensity!B12 -> TRUE | F12: =ICIO_intensity!E12 -> 0.66676672 | G12: =ICIO_intensity!H12 -> 0.33323328 | H12: =SUMIFS(BOM_raw!$E$2:$E$1001,BOM_raw!$A$2:$A$1001,$C12,BOM_raw!$F$2:$F$1001,"T") -> 0.29 | I12: =SUMIFS(BOM_raw!$E$2:$E$1001,BOM_raw!$A$2:$A$1001,$C12,BOM_raw!$F$2:$F$1001,"M") -> 0.036 | J12: =SUMIFS(BOM_raw!$E$2:$E$1001,BOM_raw!$A$2:$A$1001,$C12,BOM_raw!$F$2:$F$1001,"E") -> 0.053 | K12: =SUMIFS(BOM_raw!$E$2:$E$1001,BOM_raw!$A$2:$A$1001,$C12,BOM_raw!$F$2:$F$1001,"I") -> 0.059 | L12: =SUMIFS(BOM_raw!$E$2:$E$1001,BOM_raw!$A$2:$A$1001,$C12,BOM_raw!$F$2:$F$1001,"EE") -> 0.103 | M12: =SUMIFS(BOM_raw!$E$2:$E$1001,BOM_raw!$A$2:$A$1001,$C12,BOM_raw!$F$2:$F$1001,"HV") -> 0.01 | N12: =SUMIFS(BOM_raw!$E$2:$E$1001,BOM_raw!$A$2:$A$1001,$C12,BOM_raw!$F$2:$F$1001,"SHARED") -> 0.449 | O12: =SUM(H12:N12) -> 1 | P12: =IF(E12,F12,0) -> 0.66676672 | Q12: =P12*H12 -> 0.19336235 | R12: =P12*I12 -> 0.024003602 | S12: =P12*J12 -> 0.035338636 | T12: =P12*K12 -> 0.039339236 | U12: =P12*L12 -> 0.068676972 | V12: =P12*M12 -> 0.0066676672 | W12: =P12*N12 -> 0.29937826 | X12: =SUM(Q12:W12) -> 0.66676672 | Y12: =X12-F12 -> 0 | Z12: =X12+G12 -> 1 | AA12: =IF(E12,IF(AND(ABS(O12-1)<0.0000001,ABS(Y12)<0.0000001,ABS(Z12-1)<0.0000001),"PASS","FAIL"),"INACTIVE") -> PASS | AB12: BOM_raw + ICIO_intensity; exact ISO3 or OTHERS fallback
